Workbook
Name diff: 'Regular Season Data'!$J:$J
Name gameid: 'Regular Season Data'!$A:$A
Name managers: 'Regular Season Data'!$D:$D
Name opponent: 'Regular Season Data'!$E:$E
Name outcome: 'Regular Season Data'!$K:$K
Name owners: References!$A$2:$A$16
Name points: 'Regular Season Data'!$I:$I
Name season: 'Regular Season Data'!$F:$F
Name years: References!$A$18:$A$30

Sheet SFFL Main Page
B1: Strickland Fantasy Football League
V2: Record for Most Points Scored
B3: Historical Regular Season Table | N3: Historical Playoffs Table | V3: Manager | W3: Opponent | X3: Season | Y3: Week | Z3: Points | AA3: Weeks Held | AC3: Average Points Per Season | AH3: Founding Brothers' Cup
A4: # | B4: Owner | C4: Win | D4: Loss | E4: Tie | F4: Pct | G4: Pts Diff | H4: Pts For | I4: Pts Per Game | J4: Avg Pts in W | K4: Avg Pts in L | L4: Avg Finish | N4: Owner | O4: Win | P4: Loss | Q4: Pct | R4: Apps | S4: Rings | T4: Division Titles | V4: Brian | W4: Emily | X4: 2013 | Y4: 1 | Z4: 148 | AA4: 18 | AC4: Year | AD4: Pts per Game | AE4: Pts in W | AF4: Pts in L | AH4: Year | AI4: Winner | AJ4: Record
A5: =RANK(F5,$F$5:$F$19) -> 11 | B5: Abby | C5: =COUNTIFS(managers,B5,outcome,"W") -> 47 | D5: =COUNTIFS(managers,B5,outcome,"L") -> 57 | E5: =COUNTIFS(managers,B5,outcome,"T") -> 0 | F5: =IFERROR((C5+(0.5*E5))/SUM(C5:E5),"") -> 0.45192308 | G5: =SUMIF(managers,B5,diff) -> -506 | H5: =SUMIF(managers,B5,points) -> 8476 | I5: =H5/COUNTIF(managers,B5) -> 81.5 | J5: =AVERAGEIFS(points,managers,'SFFL Main Page'!B5,outcome,"W") -> 95.489362 | K5: =AVERAGEIFS(points,managers,'SFFL Main Page'!B5,outcome,"L") -> 69.964912 | L5: =AVERAGEIFS('Final Tables'!I:I,'Final Tables'!D:D,'SFFL Main Page'!B5) -> 6.75 | M5: AKCOVA | N5: Abby | O5: =COUNTIFS('Playoff Data'!$B:$B,'SFFL Main Page'!N5,'Playoff Data'!$H:$H,"W") -> 3 | P5: =COUNTIFS('Playoff Data'!$B:$B,'SFFL Main Page'!N5,'Playoff Data'!$H:$H,"L") -> 4 | Q5: =IFERROR((O5)/SUM(O5:P5),"") -> 0.42857143 | R5: =COUNTIFS('Final Tables'!D:D,'SFFL Main Page'!N5,'Final Tables'!Q:Q,"Y") -> 4 | S5: =COUNTIFS('Final Tables'!J:J,"1",'Final Tables'!D:D,'SFFL Main Page'!N5) -> 0 | T5: =COUNTIFS('Final Tables'!D:D,'SFFL Main Page'!N5,'Final Tables'!R:R,"Y") -> 0 | V5: Brian | W5: Russell | X5: 2014 | Y5: 6 | Z5: 149 | AA5: 2 | AC5: 2013 | AD5: =AVERAGEIF(season,'SFFL Main Page'!AC5,points) -> 90.392308 | AE5: =AVERAGEIFS(points,season,'SFFL Main Page'!AC5,outcome,"W") -> 101.96875 | AF5: =AVERAGEIFS(points,season,'SFFL Main Page'!AC5,outcome,"L") -> 79.109375 | AH5: 2013 | AI5: Russell | AJ5: =AK5&"-"&AL5 -> 4-1 | AK5: 4 | AL5: 1
A6: =RANK(F6,$F$5:$F$19) -> 12 | B6: Arnold | C6: =COUNTIFS(managers,B6,outcome,"W") -> 29 | D6: =COUNTIFS(managers,B6,outcome,"L") -> 41 | E6: =COUNTIFS(managers,B6,outcome,"T") -> 0 | F6: =IFERROR((C6+(0.5*E6))/SUM(C6:E6),"") -> 0.41428571 | G6: =SUMIF(managers,B6,diff) -> -563 | H6: =SUMIF(managers,B6,points) -> 6497 | I6: =H6/COUNTIF(managers,B6) -> 92.814286 | J6: =AVERAGEIFS(points,managers,'SFFL Main Page'!B6,outcome,"W") -> 108.68966 | K6: =AVERAGEIFS(points,managers,'SFFL Main Page'!B6,outcome,"L") -> 81.585366 | L6: =AVERAGEIFS('Final Tables'!I:I,'Final Tables'!D:D,'SFFL Main Page'!B6) -> 8.8 | M6: AKCOVA | N6: Arnold | O6: =COUNTIFS('Playoff Data'!$B:$B,'SFFL Main Page'!N6,'Playoff Data'!$H:$H,"W") -> 0 | P6: =COUNTIFS('Playoff Data'!$B:$B,'SFFL Main Page'!N6,'Playoff Data'!$H:$H,"L") -> 1 | Q6: =IFERROR((O6)/SUM(O6:P6),"") -> 0 | R6: =COUNTIFS('Final Tables'!D:D,'SFFL Main Page'!N6,'Final Tables'!Q:Q,"Y") -> 1 | S6: =COUNTIFS('Final Tables'!J:J,"1",'Final Tables'!D:D,'SFFL Main Page'!N6) -> 0 | T6: =COUNTIFS('Final Tables'!D:D,'SFFL Main Page'!N6,'Final Tables'!R:R,"Y") -> 0 | V6: Watty | W6: Emily | X6: 2014 | Y6: 8 | Z6: 157 | AA6: 62 | AC6: 2014 | AD6: =AVERAGEIF(season,'SFFL Main Page'!AC6,points) -> 89.492308 | AE6: =AVERAGEIFS(points,season,'SFFL Main Page'!AC6,outcome,"W") -> 100.55556 | AF6: =AVERAGEIFS(points,season,'SFFL Main Page'!AC6,outcome,"L") -> 78.142857 | AH6: 2014 | AI6: Russell | AJ6: =AK6&"-"&AL6 -> 4-1 | AK6: 4 | AL6: 1
A7: =RANK(F7,$F$5:$F$19) -> 6 | B7: BR | C7: =COUNTIFS(managers,B7,outcome,"W") -> 87 | D7: =COUNTIFS(managers,B7,outcome,"L") -> 84 | E7: =COUNTIFS(managers,B7,outcome,"T") -> 3 | F7: =IFERROR((C7+(0.5*E7))/SUM(C7:E7),"") -> 0.50862069 | G7: =SUMIF(managers,B7,diff) -> -251 | H7: =SUMIF(managers,B7,points) -> 15658 | I7: =H7/COUNTIF(managers,B7) -> 89.988506 | J7: =AVERAGEIFS(points,managers,'SFFL Main Page'!B7,outcome,"W") -> 101.77011 | K7: =AVERAGEIFS(points,managers,'SFFL Main Page'!B7,outcome,"L") -> 77.940476 | L7: =AVERAGEIFS('Final Tables'!I:I,'Final Tables'!D:D,'SFFL Main Page'!B7) -> 6.2307692 | M7: AKCOVA | N7: BR | O7: =COUNTIFS('Playoff Data'!$B:$B,'SFFL Main Page'!N7,'Playoff Data'!$H:$H,"W") -> 7 | P7: =COUNTIFS('Playoff Data'!$B:$B,'SFFL Main Page'!N7,'Playoff Data'!$H:$H,"L") -> 6 | Q7: =IFERROR((O7)/SUM(O7:P7),"") -> 0.53846154 | R7: =COUNTIFS('Final Tables'!D:D,'SFFL Main Page'!N7,'Final Tables'!Q:Q,"Y") -> 8 | S7: =COUNTIFS('Final Tables'!J:J,"1",'Final Tables'!D:D,'SFFL Main Page'!N7) -> 2 | T7: =COUNTIFS('Final Tables'!D:D,'SFFL Main Page'!N7,'Final Tables'!R:R,"Y") -> 2 | V7: Brent | W7: Emily | X7: 2019 | Y7: 5 | Z7: 161 | AA7: 10 | AC7: 2015 | AD7: =AVERAGEIF(season,'SFFL Main Page'!AC7,points) -> 83.544872 | AE7: =AVERAGEIFS(points,season,'SFFL Main Page'!AC7,outcome,"W") -> 94.692308 | AF7: =AVERAGEIFS(points,season,'SFFL Main Page'!AC7,outcome,"L") -> 72.397436 | AH7: 2015 | AI7: David | AJ7: =AK7&"-"&AL7 -> 3-1 | AK7: 3 | AL7: 1
A8: =RANK(F8,$F$5:$F$19) -> 1 | B8: Brent | C8: =COUNTIFS(managers,B8,outcome,"W") -> 95 | D8: =COUNTIFS(managers,B8,outcome,"L") -> 52 | E8: =COUNTIFS(managers,B8,outcome,"T") -> 1 | F8: =IFERROR((C8+(0.5*E8))/SUM(C8:E8),"") -> 0.64527027 | G8: =SUMIF(managers,B8,diff) -> 1259 | H8: =SUMIF(managers,B8,points) -> 14439 | I8: =H8/COUNTIF(managers,B8) -> 97.560811 | J8: =AVERAGEIFS(points,managers,'SFFL Main Page'!B8,outcome,"W") -> 105.35789 | K8: =AVERAGEIFS(points,managers,'SFFL Main Page'!B8,outcome,"L") -> 83.576923 | L8: =AVERAGEIFS('Final Tables'!I:I,'Final Tables'!D:D,'SFFL Main Page'!B8) -> 4.1818182 | M8: TEXAROK | N8: Brent | O8: =COUNTIFS('Playoff Data'!$B:$B,'SFFL Main Page'!N8,'Playoff Data'!$H:$H,"W") -> 4 | P8: =COUNTIFS('Playoff Data'!$B:$B,'SFFL Main Page'!N8,'Playoff Data'!$H:$H,"L") -> 8 | Q8: =IFERROR((O8)/SUM(O8:P8),"") -> 0.33333333 | R8: =COUNTIFS('Final Tables'!D:D,'SFFL Main Page'!N8,'Final Tables'!Q:Q,"Y") -> 9 | S8: =COUNTIFS('Final Tables'!J:J,"1",'Final Tables'!D:D,'SFFL Main Page'!N8) -> 1 | T8: =COUNTIFS('Final Tables'!D:D,'SFFL Main Page'!N8,'Final Tables'!R:R,"Y") -> 5 | V8: Charles | W8: Mark | X8: 2020 | Y8: 2 | Z8: 163 | AA8: 16 | AC8: 2016 | AD8: =AVERAGEIF(season,'SFFL Main Page'!AC8,points) -> 87.679487 | AE8: =AVERAGEIFS(points,season,'SFFL Main Page'!AC8,outcome,"W") -> 99.576923 | AF8: =AVERAGEIFS(points,season,'SFFL Main Page'!AC8,outcome,"L") -> 75.782051 | AH8: 2016 | AI8: David | AJ8: =AK8&"-"&AL8 -> 5-0 | AK8: 5 | AL8: 0
A9: =RANK(F9,$F$5:$F$19) -> 2 | B9: Brian | C9: =COUNTIFS(managers,B9,outcome,"W") -> 96 | D9: =COUNTIFS(managers,B9,outcome,"L") -> 77 | E9: =COUNTIFS(managers,B9,outcome,"T") -> 1 | F9: =IFERROR((C9+(0.5*E9))/SUM(C9:E9),"") -> 0.5545977 | G9: =SUMIF(managers,B9,diff) -> 286 | H9: =SUMIF(managers,B9,points) -> 16005 | I9: =H9/COUNTIF(managers,B9) -> 91.982759 | J9: =AVERAGEIFS(points,managers,'SFFL Main Page'!B9,outcome,"W") -> 103.55208 | K9: =AVERAGEIFS(points,managers,'SFFL Main Page'!B9,outcome,"L") -> 77.532468 | L9: =AVERAGEIFS('Final Tables'!I:I,'Final Tables'!D:D,'SFFL Main Page'!B9) -> 6.2307692 | M9: TEXAROK | N9: Brian | O9: =COUNTIFS('Playoff Data'!$B:$B,'SFFL Main Page'!N9,'Playoff Data'!$H:$H,"W") -> 4 | P9: =COUNTIFS('Playoff Data'!$B:$B,'SFFL Main Page'!N9,'Playoff Data'!$H:$H,"L") -> 5 | Q9: =IFERROR((O9)/SUM(O9:P9),"") -> 0.44444444 | R9: =COUNTIFS('Final Tables'!D:D,'SFFL Main Page'!N9,'Final Tables'!Q:Q,"Y") -> 6 | S9: =COUNTIFS('Final Tables'!J:J,"1",'Final Tables'!D:D,'SFFL Main Page'!N9) -> 1 | T9: =COUNTIFS('Final Tables'!D:D,'SFFL Main Page'!N9,'Final Tables'!R:R,"Y") -> 3 | V9: BR | W9: Watty | X9: 2021 | Y9: 5 | Z9: 174 | AA9: 24 | AC9: 2017 | AD9: =AVERAGEIF(season,'SFFL Main Page'!AC9,points) -> 83.762821 | AE9: =AVERAGEIFS(points,season,'SFFL Main Page'!AC9,outcome,"W") -> 94.207792 | AF9: =AVERAGEIFS(points,season,'SFFL Main Page'!AC9,outcome,"L") -> 73.155844 | AH9: 2017 | AI9: Watty | AJ9: =AK9&"-"&AL9 -> 4-1 | AK9: 4 | AL9: 1
A10: =RANK(F10,$F$5:$F$19) -> 3 | B10: Charles | C10: =COUNTIFS(managers,B10,outcome,"W") -> 82 | D10: =COUNTIFS(managers,B10,outcome,"L") -> 66 | E10: =COUNTIFS(managers,B10,outcome,"T") -> 0 | F10: =IFERROR((C10+(0.5*E10))/SUM(C10:E10),"") -> 0.55405405 | G10: =SUMIF(managers,B10,diff) -> 1025.1 | H10: =SUMIF(managers,B10,points) -> 14511.1 | I10: =H10/COUNTIF(managers,B10) -> 98.047973 | J10: =AVERAGEIFS(points,managers,'SFFL Main Page'!B10,outcome,"W") -> 108.74512 | K10: =AVERAGEIFS(points,managers,'SFFL Main Page'!B10,outcome,"L") -> 84.757576 | L10: =AVERAGEIFS('Final Tables'!I:I,'Final Tables'!D:D,'SFFL Main Page'!B10) -> 4.7272727 | M10: AKCOVA | N10: Charles | O10: =COUNTIFS('Playoff Data'!$B:$B,'SFFL Main Page'!N10,'Playoff Data'!$H:$H,"W") -> 9 | P10: =COUNTIFS('Playoff Data'!$B:$B,'SFFL Main Page'!N10,'Playoff Data'!$H:$H,"L") -> 6 | Q10: =IFERROR((O10)/SUM(O10:P10),"") -> 0.6 | R10: =COUNTIFS('Final Tables'!D:D,'SFFL Main Page'!N10,'Final Tables'!Q:Q,"Y") -> 8 | S10: =COUNTIFS('Final Tables'!J:J,"1",'Final Tables'!D:D,'SFFL Main Page'!N10) -> 2 | T10: =COUNTIFS('Final Tables'!D:D,'SFFL Main Page'!N10,'Final Tables'!R:R,"Y") -> 5 | AC10: 2018 | AD10: =AVERAGEIF(season,'SFFL Main Page'!AC10,points) -> 91.557692 | AE10: =AVERAGEIFS(points,season,'SFFL Main Page'!AC10,outcome,"W") -> 103.96104 | AF10: =AVERAGEIFS(points,season,'SFFL Main Page'!AC10,outcome,"L") -> 79.090909 | AH10: 2018 | AI10: BR | AJ10: =AK10&"-"&AL10 -> 5-1 | AK10: 5 | AL10: 1
A11: =RANK(F11,$F$5:$F$19) -> 7 | B11: David | C11: =COUNTIFS(managers,B11,outcome,"W") -> 85 | D11: =COUNTIFS(managers,B11,outcome,"L") -> 88 | E11: =COUNTIFS(managers,B11,outcome,"T") -> 1 | F11: =IFERROR((C11+(0.5*E11))/SUM(C11:E11),"") -> 0.49137931 | G11: =SUMIF(managers,B11,diff) -> -161 | H11: =SUMIF(managers,B11,points) -> 15556 | I11: =H11/COUNTIF(managers,B11) -> 89.402299 | J11: =AVERAGEIFS(points,managers,'SFFL Main Page'!B11,outcome,"W") -> 101.07059 | K11: =AVERAGEIFS(points,managers,'SFFL Main Page'!B11,outcome,"L") -> 78.125 | L11: =AVERAGEIFS('Final Tables'!I:I,'Final Tables'!D:D,'SFFL Main Page'!B11) -> 6.6923077 | M11: TEXAROK | N11: David | O11: =COUNTIFS('Playoff Data'!$B:$B,'SFFL Main Page'!N11,'Playoff Data'!$H:$H,"W") -> 5 | P11: =COUNTIFS('Playoff Data'!$B:$B,'SFFL Main Page'!N11,'Playoff Data'!$H:$H,"L") -> 8 | Q11: =IFERROR((O11)/SUM(O11:P11),"") -> 0.38461538 | R11: =COUNTIFS('Final Tables'!D:D,'SFFL Main Page'!N11,'Final Tables'!Q:Q,"Y") -> 8 | S11: =COUNTIFS('Final Tables'!J:J,"1",'Final Tables'!D:D,'SFFL Main Page'!N11) -> 0 | T11: =COUNTIFS('Final Tables'!D:D,'SFFL Main Page'!N11,'Final Tables'!R:R,"Y") -> 1 | V11: Highest Regular Season Weeks | AC11: 2019 | AD11: =AVERAGEIF(season,'SFFL Main Page'!AC11,points) -> 88.724359 | AE11: =AVERAGEIFS(points,season,'SFFL Main Page'!AC11,outcome,"W") -> 100.17949 | AF11: =AVERAGEIFS(points,season,'SFFL Main Page'!AC11,outcome,"L") -> 77.269231 | AH11: 2019 | AI11: Russell | AJ11: =AK11&"-"&AL11 -> 3-1 | AK11: 3 | AL11: 1
A12: =RANK(F12,$F$5:$F$19) -> 9 | B12: Emily | C12: =COUNTIFS(managers,B12,outcome,"W") -> 81 | D12: =COUNTIFS(managers,B12,outcome,"L") -> 92 | E12: =COUNTIFS(managers,B12,outcome,"T") -> 1 | F12: =IFERROR((C12+(0.5*E12))/SUM(C12:E12),"") -> 0.4683908 | G12: =SUMIF(managers,B12,diff) -> -766 | H12: =SUMIF(managers,B12,points) -> 15180 | I12: =H12/COUNTIF(managers,B12) -> 87.241379 | J12: =AVERAGEIFS(points,managers,'SFFL Main Page'!B12,outcome,"W") -> 100.82716 | K12: =AVERAGEIFS(points,managers,'SFFL Main Page'!B12,outcome,"L") -> 75.369565 | L12: =AVERAGEIFS('Final Tables'!I:I,'Final Tables'!D:D,'SFFL Main Page'!B12) -> 7.6363636 | M12: TEXAROK | N12: Emily | O12: =COUNTIFS('Playoff Data'!$B:$B,'SFFL Main Page'!N12,'Playoff Data'!$H:$H,"W") -> 5 | P12: =COUNTIFS('Playoff Data'!$B:$B,'SFFL Main Page'!N12,'Playoff Data'!$H:$H,"L") -> 4 | Q12: =IFERROR((O12)/SUM(O12:P12),"") -> 0.55555556 | R12: =COUNTIFS('Final Tables'!D:D,'SFFL Main Page'!N12,'Final Tables'!Q:Q,"Y") -> 4 | S12: =COUNTIFS('Final Tables'!J:J,"1",'Final Tables'!D:D,'SFFL Main Page'!N12) -> 0 | T12: =COUNTIFS('Final Tables'!D:D,'SFFL Main Page'!N12,'Final Tables'!R:R,"Y") -> 1 | V12: Rank | W12: Owner | X12: Season | Y12: Week | Z12: Pts Scored | AA12: Opponent | AC12: 2020 | AD12: =AVERAGEIF(season,'SFFL Main Page'!AC12,points) -> 88.602564 | AE12: =AVERAGEIFS(points,season,'SFFL Main Page'!AC12,outcome,"W") -> 102.37179 | AF12: =AVERAGEIFS(points,season,'SFFL Main Page'!AC12,outcome,"L") -> 74.833333 | AH12: 2020 | AI12: Watty | AJ12: =AK12&"-"&AL12 -> 3-2 | AK12: 3 | AL12: 2
A13: =RANK(F15,$F$5:$F$19) -> 13 | B13: Grayson | C13: =COUNTIFS(managers,B13,outcome,"W") -> 9 | D13: =COUNTIFS(managers,B13,outcome,"L") -> 19 | E13: =COUNTIFS(managers,B13,outcome,"T") -> 0 | F13: =IFERROR((C13+(0.5*E13))/SUM(C13:E13),"") -> 0.32142857 | G13: =SUMIF(managers,B13,diff) -> -213 | H13: =SUMIF(managers,B13,points) -> 2873 | I13: =H13/COUNTIF(managers,B13) -> 102.60714 | J13: =AVERAGEIFS(points,managers,'SFFL Main Page'!B13,outcome,"W") -> 122.55556 | K13: =AVERAGEIFS(points,managers,'SFFL Main Page'!B13,outcome,"L") -> 93.157895 | L13: =AVERAGEIFS('Final Tables'!I:I,'Final Tables'!D:D,'SFFL Main Page'!B13) -> 12.5 | M13: AKCOVA | N13: Grayson | O13: =COUNTIFS('Playoff Data'!$B:$B,'SFFL Main Page'!N13,'Playoff Data'!$H:$H,"W") -> 0 | P13: =COUNTIFS('Playoff Data'!$B:$B,'SFFL Main Page'!N13,'Playoff Data'!$H:$H,"L") -> 0 | Q13: =IFERROR((O13)/SUM(O13:P13),"") | R13: =COUNTIFS('Final Tables'!D:D,'SFFL Main Page'!N13,'Final Tables'!Q:Q,"Y") -> 0 | S13: =COUNTIFS('Final Tables'!J:J,"1",'Final Tables'!D:D,'SFFL Main Page'!N13) -> 0 | T13: =COUNTIFS('Final Tables'!D:D,'SFFL Main Page'!N13,'Final Tables'!R:R,"Y") -> 0 | V13: 1 | W13: =VLOOKUP(V13,'Regular Season Data'!C:I,2,FALSE) -> BR | X13: =VLOOKUP(V13,'Regular Season Data'!C:I,4,FALSE) -> 2021 | Y13: =VLOOKUP(V13,'Regular Season Data'!C:I,5,FALSE) -> 5 | Z13: =VLOOKUP(V13,'Regular Season Data'!C:I,7,FALSE) -> 174 | AA13: =VLOOKUP(V13,'Regular Season Data'!C:I,3,FALSE) -> Watty | AC13: 2021 | AD13: =AVERAGEIF(season,'SFFL Main Page'!AC13,points) -> 89.214286 | AE13: =AVERAGEIFS(points,season,'SFFL Main Page'!AC13,outcome,"W") -> 102.25301 | AF13: =AVERAGEIFS(points,season,'SFFL Main Page'!AC13,outcome,"L") -> 76.301205 | AH13: 2021 | AI13: Russell | AJ13: =AK13&"-"&AL13 -> 3-1 | AK13: 3 | AL13: 1
A14: =RANK(F16,$F$5:$F$19) -> 10 | B14: Jordan | C14: =COUNTIFS(managers,B14,outcome,"W") -> 11 | D14: =COUNTIFS(managers,B14,outcome,"L") -> 17 | E14: =COUNTIFS(managers,B14,outcome,"T") -> 0 | F14: =IFERROR((C14+(0.5*E14))/SUM(C14:E14),"") -> 0.39285714 | G14: =SUMIF(managers,B14,diff) -> -151 | H14: =SUMIF(managers,B14,points) -> 2975 | I14: =H14/COUNTIF(managers,B14) -> 106.25 | J14: =AVERAGEIFS(points,managers,'SFFL Main Page'!B14,outcome,"W") -> 119.72727 | K14: =AVERAGEIFS(points,managers,'SFFL Main Page'!B14,outcome,"L") -> 97.529412 | L14: =AVERAGEIFS('Final Tables'!I:I,'Final Tables'!D:D,'SFFL Main Page'!B14) -> 8 | M14: TEXAROK | N14: Jordan | O14: =COUNTIFS('Playoff Data'!$B:$B,'SFFL Main Page'!N14,'Playoff Data'!$H:$H,"W") -> 2 | P14: =COUNTIFS('Playoff Data'!$B:$B,'SFFL Main Page'!N14,'Playoff Data'!$H:$H,"L") -> 1 | Q14: =IFERROR((O14)/SUM(O14:P14),"") -> 0.66666667 | R14: =COUNTIFS('Final Tables'!D:D,'SFFL Main Page'!N14,'Final Tables'!Q:Q,"Y") -> 1 | S14: =COUNTIFS('Final Tables'!J:J,"1",'Final Tables'!D:D,'SFFL Main Page'!N14) -> 0 | T14: =COUNTIFS('Final Tables'!D:D,'SFFL Main Page'!N14,'Final Tables'!R:R,"Y") -> 0 | V14: 2 | W14: =VLOOKUP(V14,'Regular Season Data'!C:I,2,FALSE) -> Brent | X14: =VLOOKUP(V14,'Regular Season Data'!C:I,4,FALSE) -> 2025 | Y14: =VLOOKUP(V14,'Regular Season Data'!C:I,5,FALSE) -> 4 | Z14: =VLOOKUP(V14,'Regular Season Data'!C:I,7,FALSE) -> 172 | AA14: =VLOOKUP(V14,'Regular Season Data'!C:I,3,FALSE) -> Charles | AC14: 2022 | AD14: =AVERAGEIF(season,'SFFL Main Page'!AC14,points) -> 86.464286 | AE14: =AVERAGEIFS(points,season,'SFFL Main Page'!AC14,outcome,"W") -> 97.940476 | AF14: =AVERAGEIFS(points,season,'SFFL Main Page'!AC14,outcome,"L") -> 74.988095 | AH14: 2022 | AI14: David | AJ14: =AK14&"-"&AL14 -> 3-1 | AK14: 3 | AL14: 1
A15: =RANK(F17,$F$5:$F$19) -> 4 | B15: Mark | C15: =COUNTIFS(managers,B15,outcome,"W") -> 71 | D15: =COUNTIFS(managers,B15,outcome,"L") -> 102 | E15: =COUNTIFS(managers,B15,outcome,"T") -> 1 | F15: =IFERROR((C15+(0.5*E15))/SUM(C15:E15),"") -> 0.41091954 | G15: =SUMIF(managers,B15,diff) -> -1107 | H15: =SUMIF(managers,B15,points) -> 15514 | I15: =H15/COUNTIF(managers,B15) -> 89.16092 | J15: =AVERAGEIFS(points,managers,'SFFL Main Page'!B15,outcome,"W") -> 102.38028 | K15: =AVERAGEIFS(points,managers,'SFFL Main Page'!B15,outcome,"L") -> 79.95098 | L15: =AVERAGEIFS('Final Tables'!I:I,'Final Tables'!D:D,'SFFL Main Page'!B15) -> 8.3076923 | M15: AKCOVA | N15: Mark | O15: =COUNTIFS('Playoff Data'!$B:$B,'SFFL Main Page'!N15,'Playoff Data'!$H:$H,"W") -> 4 | P15: =COUNTIFS('Playoff Data'!$B:$B,'SFFL Main Page'!N15,'Playoff Data'!$H:$H,"L") -> 2 | Q15: =IFERROR((O15)/SUM(O15:P15),"") -> 0.66666667 | R15: =COUNTIFS('Final Tables'!D:D,'SFFL Main Page'!N15,'Final Tables'!Q:Q,"Y") -> 3 | S15: =COUNTIFS('Final Tables'!J:J,"1",'Final Tables'!D:D,'SFFL Main Page'!N15) -> 1 | T15: =COUNTIFS('Final Tables'!D:D,'SFFL Main Page'!N15,'Final Tables'!R:R,"Y") -> 2 | V15: 3 | W15: =VLOOKUP(V15,'Regular Season Data'!C:I,2,FALSE) -> Russell | X15: =VLOOKUP(V15,'Regular Season Data'!C:I,4,FALSE) -> 2025 | Y15: =VLOOKUP(V15,'Regular Season Data'!C:I,5,FALSE) -> 4 | Z15: =VLOOKUP(V15,'Regular Season Data'!C:I,7,FALSE) -> 171 | AA15: =VLOOKUP(V15,'Regular Season Data'!C:I,3,FALSE) -> Emily | AC15: 2023 | AD15: =AVERAGEIF(season,'SFFL Main Page'!AC15,points) -> 88.541667 | AE15: =AVERAGEIFS(points,season,'SFFL Main Page'!AC15,outcome,"W") -> 101.28571 | AF15: =AVERAGEIFS(points,season,'SFFL Main Page'!AC15,outcome,"L") -> 75.797619 | AH15: 2023 | AI15: Watty | AJ15: =AK15&"-"&AL15 -> 5-1 | AK15: 5 | AL15: 1
A16: =RANK(F18,$F$5:$F$19) -> 5 | B16: Matt | C16: =COUNTIFS(managers,B16,outcome,"W") -> 80 | D16: =COUNTIFS(managers,B16,outcome,"L") -> 93 | E16: =COUNTIFS(managers,B16,outcome,"T") -> 1 | F16: =IFERROR((C16+(0.5*E16))/SUM(C16:E16),"") -> 0.46264368 | G16: =SUMIF(managers,B16,diff) -> -70 | H16: =SUMIF(managers,B16,points) -> 15933 | I16: =H16/COUNTIF(managers,B16) -> 91.568966 | J16: =AVERAGEIFS(points,managers,'SFFL Main Page'!B16,outcome,"W") -> 102.9 | K16: =AVERAGEIFS(points,managers,'SFFL Main Page'!B16,outcome,"L") -> 81.935484 | L16: =AVERAGEIFS('Final Tables'!I:I,'Final Tables'!D:D,'SFFL Main Page'!B16) -> 6.6153846 | M16: TEXAROK | N16: Matt | O16: =COUNTIFS('Playoff Data'!$B:$B,'SFFL Main Page'!N16,'Playoff Data'!$H:$H,"W") -> 3 | P16: =COUNTIFS('Playoff Data'!$B:$B,'SFFL Main Page'!N16,'Playoff Data'!$H:$H,"L") -> 7 | Q16: =IFERROR((O16)/SUM(O16:P16),"") -> 0.3 | R16: =COUNTIFS('Final Tables'!D:D,'SFFL Main Page'!N16,'Final Tables'!Q:Q,"Y") -> 7 | S16: =COUNTIFS('Final Tables'!J:J,"1",'Final Tables'!D:D,'SFFL Main Page'!N16) -> 0 | T16: =COUNTIFS('Final Tables'!D:D,'SFFL Main Page'!N16,'Final Tables'!R:R,"Y") -> 2 | V16: 4 | W16: =VLOOKUP(V16,'Regular Season Data'!C:I,2,FALSE) -> BR | X16: =VLOOKUP(V16,'Regular Season Data'!C:I,4,FALSE) -> 2024 | Y16: =VLOOKUP(V16,'Regular Season Data'!C:I,5,FALSE) -> 8 | Z16: =VLOOKUP(V16,'Regular Season Data'!C:I,7,FALSE) -> 169 | AA16: =VLOOKUP(V16,'Regular Season Data'!C:I,3,FALSE) -> Brian | AC16: 2024 | AD16: =AVERAGEIF(season,'SFFL Main Page'!AC16,points) -> 108.30612 | AE16: =AVERAGEIFS(points,season,'SFFL Main Page'!AC16,outcome,"W") -> 120.55102 | AF16: =AVERAGEIFS(points,season,'SFFL Main Page'!AC16,outcome,"L") -> 96.061224 | AH16: 2024 | AI16: Russell | AJ16: =AK16&"-"&AL16 -> 3-1 | AK16: 3 | AL16: 1
A17: =RANK(F19,$F$5:$F$19) -> 8 | B17: Michael | C17: =COUNTIFS(managers,B17,outcome,"W") -> 94 | D17: =COUNTIFS(managers,B17,outcome,"L") -> 79 | E17: =COUNTIFS(managers,B17,outcome,"T") -> 1 | F17: =IFERROR((C17+(0.5*E17))/SUM(C17:E17),"") -> 0.54310345 | G17: =SUMIF(managers,B17,diff) -> 278 | H17: =SUMIF(managers,B17,points) -> 16154 | I17: =H17/COUNTIF(managers,B17) -> 92.83908 | J17: =AVERAGEIFS(points,managers,'SFFL Main Page'!B17,outcome,"W") -> 102.92553 | K17: =AVERAGEIFS(points,managers,'SFFL Main Page'!B17,outcome,"L") -> 80.632911 | L17: =AVERAGEIFS('Final Tables'!I:I,'Final Tables'!D:D,'SFFL Main Page'!B17) -> 5.3846154 | M17: AKCOVA | N17: Michael | O17: =COUNTIFS('Playoff Data'!$B:$B,'SFFL Main Page'!N17,'Playoff Data'!$H:$H,"W") -> 5 | P17: =COUNTIFS('Playoff Data'!$B:$B,'SFFL Main Page'!N17,'Playoff Data'!$H:$H,"L") -> 6 | Q17: =IFERROR((O17)/SUM(O17:P17),"") -> 0.45454545 | R17: =COUNTIFS('Final Tables'!D:D,'SFFL Main Page'!N17,'Final Tables'!Q:Q,"Y") -> 8 | S17: =COUNTIFS('Final Tables'!J:J,"1",'Final Tables'!D:D,'SFFL Main Page'!N17) -> 2 | T17: =COUNTIFS('Final Tables'!D:D,'SFFL Main Page'!N17,'Final Tables'!R:R,"Y") -> 3 | V17: 5 | W17: =VLOOKUP(V17,'Regular Season Data'!C:I,2,FALSE) -> Mark | X17: =VLOOKUP(V17,'Regular Season Data'!C:I,4,FALSE) -> 2025 | Y17: =VLOOKUP(V17,'Regular Season Data'!C:I,5,FALSE) -> 8 | Z17: =VLOOKUP(V17,'Regular Season Data'!C:I,7,FALSE) -> 167 | AA17: =VLOOKUP(V17,'Regular Season Data'!C:I,3,FALSE) -> David | AC17: Non-PPR | AD17: =AVERAGE(AD5:AD15) -> 87.997877 | AE17: =AVERAGE(AE5:AE15) -> 99.908441 | AF17: =AVERAGE(AF5:AF15) -> 76.078905
B18: Russell | C18: =COUNTIFS(managers,B18,outcome,"W") -> 90 | D18: =COUNTIFS(managers,B18,outcome,"L") -> 82 | E18: =COUNTIFS(managers,B18,outcome,"T") -> 2 | F18: =IFERROR((C18+(0.5*E18))/SUM(C18:E18),"") -> 0.52298851 | G18: =SUMIF(managers,B18,diff) -> 779.9 | H18: =SUMIF(managers,B18,points) -> 16395 | I18: =H18/COUNTIF(managers,B18) -> 94.224138 | J18: =AVERAGEIFS(points,managers,'SFFL Main Page'!B18,outcome,"W") -> 106.33333 | K18: =AVERAGEIFS(points,managers,'SFFL Main Page'!B18,outcome,"L") -> 80.914634 | L18: =AVERAGEIFS('Final Tables'!I:I,'Final Tables'!D:D,'SFFL Main Page'!B18) -> 5.6923077 | M18: TEXAROK | N18: Russell | O18: =COUNTIFS('Playoff Data'!$B:$B,'SFFL Main Page'!N18,'Playoff Data'!$H:$H,"W") -> 11 | P18: =COUNTIFS('Playoff Data'!$B:$B,'SFFL Main Page'!N18,'Playoff Data'!$H:$H,"L") -> 7 | Q18: =IFERROR((O18)/SUM(O18:P18),"") -> 0.61111111 | R18: =COUNTIFS('Final Tables'!D:D,'SFFL Main Page'!N18,'Final Tables'!Q:Q,"Y") -> 9 | S18: =COUNTIFS('Final Tables'!J:J,"1",'Final Tables'!D:D,'SFFL Main Page'!N18) -> 2 | T18: =COUNTIFS('Final Tables'!D:D,'SFFL Main Page'!N18,'Final Tables'!R:R,"Y") -> 1 | V18: 6 | W18: =VLOOKUP(V18,'Regular Season Data'!C:I,2,FALSE) -> Jordan | X18: =VLOOKUP(V18,'Regular Season Data'!C:I,4,FALSE) -> 2024 | Y18: =VLOOKUP(V18,'Regular Season Data'!C:I,5,FALSE) -> 2 | Z18: =VLOOKUP(V18,'Regular Season Data'!C:I,7,FALSE) -> 165 | AA18: =VLOOKUP(V18,'Regular Season Data'!C:I,3,FALSE) -> Grayson | AC18: PPR% Inc | AD18: =(AD16-AD17)/AD17 -> 0.23078108 | AE18: =(AE16-AE17)/AE17 -> 0.20661497 | AF18: =(AF16-AF17)/AF17 -> 0.26265256
B19: Watty | C19: =COUNTIFS(managers,B19,outcome,"W") -> 83 | D19: =COUNTIFS(managers,B19,outcome,"L") -> 91 | E19: =COUNTIFS(managers,B19,outcome,"T") -> 0 | F19: =IFERROR((C19+(0.5*E19))/SUM(C19:E19),"") -> 0.47701149 | G19: =SUMIF(managers,B19,diff) -> 160 | H19: =SUMIF(managers,B19,points) -> 15662 | I19: =H19/COUNTIF(managers,B19) -> 90.011494 | J19: =AVERAGEIFS(points,managers,'SFFL Main Page'!B19,outcome,"W") -> 104.75904 | K19: =AVERAGEIFS(points,managers,'SFFL Main Page'!B19,outcome,"L") -> 76.56044 | L19: =AVERAGEIFS('Final Tables'!I:I,'Final Tables'!D:D,'SFFL Main Page'!B19) -> 7.3846154 | M19: AKCOVA | N19: Watty | O19: =COUNTIFS('Playoff Data'!$B:$B,'SFFL Main Page'!N19,'Playoff Data'!$H:$H,"W") -> 7 | P19: =COUNTIFS('Playoff Data'!$B:$B,'SFFL Main Page'!N19,'Playoff Data'!$H:$H,"L") -> 4 | Q19: =IFERROR((O19)/SUM(O19:P19),"") -> 0.63636364 | R19: =COUNTIFS('Final Tables'!D:D,'SFFL Main Page'!N19,'Final Tables'!Q:Q,"Y") -> 6 | S19: =COUNTIFS('Final Tables'!J:J,"1",'Final Tables'!D:D,'SFFL Main Page'!N19) -> 2 | T19: =COUNTIFS('Final Tables'!D:D,'SFFL Main Page'!N19,'Final Tables'!R:R,"Y") -> 1 | V19: 7 | W19: =VLOOKUP(V19,'Regular Season Data'!C:I,2,FALSE) -> Mark | X19: =VLOOKUP(V19,'Regular Season Data'!C:I,4,FALSE) -> 2024 | Y19: =VLOOKUP(V19,'Regular Season Data'!C:I,5,FALSE) -> 10 | Z19: =VLOOKUP(V19,'Regular Season Data'!C:I,7,FALSE) -> 164 | AA19: =VLOOKUP(V19,'Regular Season Data'!C:I,3,FALSE) -> Watty
B20: Overall | C20: =SUM(C5:C19) -> 1040 | D20: =SUM(D5:D19) -> 1040 | E20: =SUM(E5:E19) -> 12 | H20: =SUM(H5:H19) -> 191828.1 | I20: =AVERAGE(points) -> 91.696033 | J20: =AVERAGEIFS(points,outcome,"W") -> 103.82702 | K20: =AVERAGEIFS(points,outcome,"L") -> 79.590385 | N20: Overall | O20: =SUM(O5:O19) -> 69 | P20: =SUM(P5:P19) -> 69 | Q20: =IFERROR((O20+(0.5*#REF!))/SUM(O20:P20),"") | V20: 8 | W20: =VLOOKUP(V20,'Regular Season Data'!C:I,2,FALSE) -> Charles | X20: =VLOOKUP(V20,'Regular Season Data'!C:I,4,FALSE) -> 2020 | Y20: =VLOOKUP(V20,'Regular Season Data'!C:I,5,FALSE) -> 2 | Z20: =VLOOKUP(V20,'Regular Season Data'!C:I,7,FALSE) -> 163 | AA20: =VLOOKUP(V20,'Regular Season Data'!C:I,3,FALSE) -> Mark
V21: 9 | W21: =VLOOKUP(V21,'Regular Season Data'!C:I,2,FALSE) -> Brent | X21: =VLOOKUP(V21,'Regular Season Data'!C:I,4,FALSE) -> 2019 | Y21: =VLOOKUP(V21,'Regular Season Data'!C:I,5,FALSE) -> 5 | Z21: =VLOOKUP(V21,'Regular Season Data'!C:I,7,FALSE) -> 161 | AA21: =VLOOKUP(V21,'Regular Season Data'!C:I,3,FALSE) -> Emily
B22: Historical Division Head to Head | F22: Top 5 Biggest Beatdowns of All Time | N22: Founding Brothers' Cup | V22: 10 | W22: =VLOOKUP(V22,'Regular Season Data'!C:I,2,FALSE) -> #N/A | X22: =VLOOKUP(V22,'Regular Season Data'!C:I,4,FALSE) -> #N/A | Y22: =VLOOKUP(V22,'Regular Season Data'!C:I,5,FALSE) -> #N/A | Z22: =VLOOKUP(V22,'Regular Season Data'!C:I,7,FALSE) -> #N/A | AA22: =VLOOKUP(V22,'Regular Season Data'!C:I,3,FALSE) -> #N/A | AE22: Year | AF22: 2025
B23: TEXAROK | D23: AKCOVA | F23: Rank | G23: Owner | H23: Opponent | I23: Pts Scored | J23: Margin | K23: Year | L23: Week | N23: Brother | O23: Win | P23: Loss | Q23: Pct | Y23: Founding Brothers vs Kids | AE23: Founding Brothers' Cup
B24: Regular Season | F24: 1 | G24: =VLOOKUP(F24,'Regular Season Data'!$B:$M,3,FALSE) -> Watty | H24: =VLOOKUP(F24,'Regular Season Data'!$B:$M,4,FALSE) -> Emily | I24: =VLOOKUP(F24,'Regular Season Data'!$B:$M,8,FALSE) -> 135 | J24: =VLOOKUP(F24,'Regular Season Data'!$B:$M,9,FALSE) -> 99 | K24: =VLOOKUP(F24,'Regular Season Data'!$B:$M,5,FALSE) -> 2019 | L24: =VLOOKUP(F24,'Regular Season Data'!$B:$M,6,FALSE) -> 9 | N24: BR | O24: {=SUM(COUNTIFS(managers,'SFFL Main Page'!N24,opponent,{"David","Russell","Watty"},outcome,"W"))} -> 19 | P24: {=SUM(COUNTIFS(managers,'SFFL Main Page'!N24,opponent,{"David","Russell","Watty"},outcome,"L"))} -> 27 | Q24: =IFERROR((O24)/SUM(O24:P24),"") -> 0.41304348 | Y24: Brother | Z24: Win | AA24: Loss | AB24: Tie | AC24: Pct | AE24: Brother | AF24: Win | AG24: Loss | AH24: Pct
A25: {=IFERROR(INDEX(gameid,MATCH(MAX(IF(managers=$C$3,IF(season=#REF!,points))),IF(opponent<>$C$3,points),0)),"")} | B25: Wins | C25: T | D25: Wins | F25: 2 | G25: =VLOOKUP(F25,'Regular Season Data'!$B:$M,3,FALSE) -> Charles | H25: =VLOOKUP(F25,'Regular Season Data'!$B:$M,4,FALSE) -> Abby | I25: =VLOOKUP(F25,'Regular Season Data'!$B:$M,8,FALSE) -> 149 | J25: =VLOOKUP(F25,'Regular Season Data'!$B:$M,9,FALSE) -> 93 | K25: =VLOOKUP(F25,'Regular Season Data'!$B:$M,5,FALSE) -> 2020 | L25: =VLOOKUP(F25,'Regular Season Data'!$B:$M,6,FALSE) -> 3 | N25: David | O25: {=SUM(COUNTIFS(managers,'SFFL Main Page'!N25,opponent,{"BR","Russell","Watty"},outcome,"W"))} -> 25 | P25: {=SUM(COUNTIFS(managers,'SFFL Main Page'!N25,opponent,{"BR","Russell","Watty"},outcome,"L"))} -> 23 | Q25: =IFERROR((O25)/SUM(O25:P25),"") -> 0.52083333 | Y25: BR | Z25: {=SUM(COUNTIFS(managers,'SFFL Main Page'!Y25,opponent,{"Charles","Arnold"},outcome,"W"))} -> 12 | AA25: {=SUM(COUNTIFS(managers,'SFFL Main Page'!Y25,opponent,{"Charles","Arnold"},outcome,"L"))} -> 10 | AB25: {=SUM(COUNTIFS(managers,'SFFL Main Page'!Y25,opponent,{"Charles","Arnold"},outcome,"T"))} -> 0 | AC25: =IFERROR((Z25)/SUM(Z25:AB25),"") -> 0.54545455 | AE25: BR | AF25: {=SUM(COUNTIFS(managers,'SFFL Main Page'!AE25,opponent,{"David","Russell","Watty"},outcome,"W",season,'SFFL Main Page'!AF22))} -> 0 | AG25: {=SUM(COUNTIFS(managers,'SFFL Main Page'!AE25,opponent,{"David","Russell","Watty"},outcome,"L",season,'SFFL Main Page'!AF22))} -> 3 | AH25: =IFERROR((AF25)/SUM(AF25:AG25),"") -> 0
B26: =COUNTIFS('Regular Season Data'!M:M,'SFFL Main Page'!B23,outcome,"W",'Regular Season Data'!N:N,"Y") -> 287 | C26: =COUNTIFS(outcome,"T",'Regular Season Data'!N:N,"Y") -> 10 | D26: =COUNTIFS('Regular Season Data'!M:M,'SFFL Main Page'!D23,outcome,"W",'Regular Season Data'!N:N,"Y") -> 253 | F26: 3 | G26: =VLOOKUP(F26,'Regular Season Data'!$B:$M,3,FALSE) -> David | H26: =VLOOKUP(F26,'Regular Season Data'!$B:$M,4,FALSE) -> Michael | I26: =VLOOKUP(F26,'Regular Season Data'!$B:$M,8,FALSE) -> 153 | J26: =VLOOKUP(F26,'Regular Season Data'!$B:$M,9,FALSE) -> 90 | K26: =VLOOKUP(F26,'Regular Season Data'!$B:$M,5,FALSE) -> 2019 | L26: =VLOOKUP(F26,'Regular Season Data'!$B:$M,6,FALSE) -> 5 | N26: Russell | O26: {=SUM(COUNTIFS(managers,'SFFL Main Page'!N26,opponent,{"BR","David","Watty"},outcome,"W"))} -> 34 | P26: {=SUM(COUNTIFS(managers,'SFFL Main Page'!N26,opponent,{"BR","David","Watty"},outcome,"L"))} -> 17 | Q26: =IFERROR((O26)/SUM(O26:P26),"") -> 0.66666667 | Y26: David | Z26: {=SUM(COUNTIFS(managers,'SFFL Main Page'!Y26,opponent,{"Brian"},outcome,"W"))} -> 6 | AA26: {=SUM(COUNTIFS(managers,'SFFL Main Page'!Y26,opponent,{"Brian"},outcome,"L"))} -> 18 | AB26: {=SUM(COUNTIFS(managers,'SFFL Main Page'!Y26,opponent,{"Brian"},outcome,"T"))} -> 0 | AC26: =IFERROR((Z26)/SUM(Z26:AB26),"") -> 0.25 | AE26: David | AF26: {=SUM(COUNTIFS(managers,'SFFL Main Page'!AE26,opponent,{"BR","Russell","Watty"},outcome,"W",season,'SFFL Main Page'!AF22))} -> 2 | AG26: {=SUM(COUNTIFS(managers,'SFFL Main Page'!AE26,opponent,{"BR","Russell","Watty"},outcome,"L",season,'SFFL Main Page'!AF22))} -> 2 | AH26: =IFERROR((AF26)/SUM(AF26:AG26),"") -> 0.5
B27: Playoffs | F27: 4 | G27: =VLOOKUP(F27,'Regular Season Data'!$B:$M,3,FALSE) -> Russell | H27: =VLOOKUP(F27,'Regular Season Data'!$B:$M,4,FALSE) -> Brian | I27: =VLOOKUP(F27,'Regular Season Data'!$B:$M,8,FALSE) -> 142 | J27: =VLOOKUP(F27,'Regular Season Data'!$B:$M,9,FALSE) -> 88 | K27: =VLOOKUP(F27,'Regular Season Data'!$B:$M,5,FALSE) -> 2023 | L27: =VLOOKUP(F27,'Regular Season Data'!$B:$M,6,FALSE) -> 4 | N27: Watty | O27: {=SUM(COUNTIFS(managers,'SFFL Main Page'!N27,opponent,{"David","Russell","BR"},outcome,"W"))} -> 20 | P27: {=SUM(COUNTIFS(managers,'SFFL Main Page'!N27,opponent,{"David","Russell","BR"},outcome,"L"))} -> 31 | Q27: =IFERROR((O27)/SUM(O27:P27),"") -> 0.39215686 | Y27: Russell | Z27: {=SUM(COUNTIFS(managers,'SFFL Main Page'!Y27,opponent,{"Emily","Matt"},outcome,"W"))} -> 10 | AA27: {=SUM(COUNTIFS(managers,'SFFL Main Page'!Y27,opponent,{"Emily","Matt"},outcome,"L"))} -> 24 | AB27: {=SUM(COUNTIFS(managers,'SFFL Main Page'!Y27,opponent,{"Emily","Matt"},outcome,"T"))} -> 1 | AC27: =IFERROR((Z27)/SUM(Z27:AB27),"") -> 0.28571429 | AE27: Russell | AF27: {=SUM(COUNTIFS(managers,'SFFL Main Page'!AE27,opponent,{"BR","David","Watty"},outcome,"W",season,'SFFL Main Page'!AF22))} -> 3 | AG27: {=SUM(COUNTIFS(managers,'SFFL Main Page'!AE27,opponent,{"BR","David","Watty"},outcome,"L",season,'SFFL Main Page'!AF22))} -> 1 | AH27: =IFERROR((AF27)/SUM(AF27:AG27),"") -> 0.75
B28: Wins | C28: T | D28: Wins | F28: 5 | G28: =VLOOKUP(F28,'Regular Season Data'!$B:$M,3,FALSE) -> Charles | H28: =VLOOKUP(F28,'Regular Season Data'!$B:$M,4,FALSE) -> Brian | I28: =VLOOKUP(F28,'Regular Season Data'!$B:$M,8,FALSE) -> 141 | J28: =VLOOKUP(F28,'Regular Season Data'!$B:$M,9,FALSE) -> 87 | K28: =VLOOKUP(F28,'Regular Season Data'!$B:$M,5,FALSE) -> 2016 | L28: =VLOOKUP(F28,'Regular Season Data'!$B:$M,6,FALSE) -> 1 | N28: Brother | O28: Win | P28: Loss | Q28: Pct | Y28: Watty | Z28: {=SUM(COUNTIFS(managers,'SFFL Main Page'!Y28,opponent,{"Abby","Mark","Michael"},outcome,"W"))} -> 23 | AA28: {=SUM(COUNTIFS(managers,'SFFL Main Page'!Y28,opponent,{"Abby","Mark","Michael"},outcome,"L"))} -> 27 | AB28: {=SUM(COUNTIFS(managers,'SFFL Main Page'!Y28,opponent,{"Abby","Mark","Michael"},outcome,"T"))} -> 0 | AC28: =IFERROR((Z28)/SUM(Z28:AB28),"") -> 0.46 | AE28: Watty | AF28: {=SUM(COUNTIFS(managers,'SFFL Main Page'!AE28,opponent,{"David","Russell","BR"},outcome,"W",season,'SFFL Main Page'!AF22))} -> 2 | AG28: {=SUM(COUNTIFS(managers,'SFFL Main Page'!AE28,opponent,{"David","Russell","BR"},outcome,"L",season,'SFFL Main Page'!AF22))} -> 1 | AH28: =IFERROR((AF28)/SUM(AF28:AG28),"") -> 0.66666667
B29: =COUNTIFS('Playoff Data'!H:H,"W",'Playoff Data'!J:J,"Y",'Playoff Data'!I:I,"TEXAROK") -> 12 | C29: 0 | D29: =COUNTIFS('Playoff Data'!H:H,"W",'Playoff Data'!J:J,"Y",'Playoff Data'!I:I,"AKCOVA") -> 16 | N29: BR | O29: {=SUM(COUNTIFS(managers,'SFFL Main Page'!N29,opponent,{"David","Russell","Watty"},outcome,"W"))} -> 19 | P29: {=SUM(COUNTIFS(managers,'SFFL Main Page'!N29,opponent,{"David","Russell","Watty"},outcome,"L"))} -> 27 | Q29: =IFERROR((O29)/SUM(O29:P29),"") -> 0.41304348 | Y29: Brother | Z29: Win | AA29: Loss | AB29: Tie | AC29: Pct
B30: Championships | F30: Woodsheds | N30: vs David | O30: =COUNTIFS(managers,$N$29,opponent,S32,outcome,"W") -> 6 | P30: =COUNTIFS(managers,$N$29,opponent,S32,outcome,"L") -> 7 | Q30: =IFERROR((O30)/SUM(O30:P30),"") -> 0.46153846 | Y30: BR | Z30: {=SUM(COUNTIFS(managers,'SFFL Main Page'!Y30,opponent,{"Charles","Arnold"},outcome,"W"))} -> 12 | AA30: {=SUM(COUNTIFS(managers,'SFFL Main Page'!Y30,opponent,{"Charles","Arnold"},outcome,"L"))} -> 10 | AB30: {=SUM(COUNTIFS(managers,'SFFL Main Page'!Y30,opponent,{"David","Russell","Watty"},outcome,"T"))} -> 0 | AC30: =IFERROR((Z30)/SUM(Z30:AB30),"") -> 0.54545455
B31: =SUMIFS(S5:S19,M5:M19,B23) -> 4 | D31: =SUMIFS(S5:S19,M5:M19,D23) -> 9 | F31: Owner | G31: For | H31: Against | I31: Delta | N31: vs Russell | O31: =COUNTIFS(managers,$N$29,opponent,S33,outcome,"W") -> 4 | P31: =COUNTIFS(managers,$N$29,opponent,S33,outcome,"L") -> 11 | Q31: =IFERROR((O31)/SUM(O31:P31),"") -> 0.26666667 | Y31: vs Charles | Z31: =COUNTIFS(managers,Y30,opponent,X32,outcome,"W") -> 8 | AA31: =COUNTIFS(managers,Y30,opponent,X32,outcome,"L") -> 9 | AB31: =COUNTIFS(managers,Y30,opponent,X32,outcome,"T") -> 0 | AC31: =IFERROR((Z31)/SUM(Z31:AB31),"") -> 0.47058824 | AD31: David
F32: Abby | G32: =COUNTIFS(managers,'SFFL Main Page'!F32,diff,">=50") -> 6 | H32: =COUNTIFS(managers,'SFFL Main Page'!F32,diff,"<=-50") -> 9 | I32: =G32-H32 -> -3 | N32: vs Watty | O32: =COUNTIFS(managers,$N$29,opponent,S34,outcome,"W") -> 9 | P32: =COUNTIFS(managers,$N$29,opponent,S34,outcome,"L") -> 9 | Q32: =IFERROR((O32)/SUM(O32:P32),"") -> 0.5 | S32: David | X32: Charles | Y32: vs Arnold | Z32: =COUNTIFS(managers,Y30,opponent,X33,outcome,"W") -> 4 | AA32: =COUNTIFS(managers,Y30,opponent,X33,outcome,"L") -> 1 | AB32: =COUNTIFS(managers,Y30,opponent,X33,outcome,"T") -> 0 | AC32: =IFERROR((Z32)/SUM(Z32:AB32),"") -> 0.8 | AD32: Russell
B33: Owner | C33: vs TEXAROK | D33: vs AKCOVA | F33: Arnold | G33: =COUNTIFS(managers,'SFFL Main Page'!F33,diff,">=50") -> 2 | H33: =COUNTIFS(managers,'SFFL Main Page'!F33,diff,"<=-50") -> 6 | I33: =G33-H33 -> -4 | N33: David | O33: {=SUM(COUNTIFS(managers,'SFFL Main Page'!N33,opponent,{"BR","Russell","Watty"},outcome,"W"))} -> 25 | P33: {=SUM(COUNTIFS(managers,'SFFL Main Page'!N33,opponent,{"BR","Russell","Watty"},outcome,"L"))} -> 23 | Q33: =IFERROR((O33)/SUM(O33:P33),"") -> 0.52083333 | S33: Russell | X33: Arnold | Y33: David | Z33: {=SUM(COUNTIFS(managers,'SFFL Main Page'!Y33,opponent,{"Brian"},outcome,"W"))} -> 6 | AA33: {=SUM(COUNTIFS(managers,'SFFL Main Page'!Y33,opponent,{"Brian"},outcome,"L"))} -> 18 | AB33: {=SUM(COUNTIFS(managers,'SFFL Main Page'!Y33,opponent,{"Brian"},outcome,"T"))} -> 0 | AC33: =IFERROR((Z33)/SUM(Z33:AB33),"") -> 0.25 | AD33: Watty
B34: Abby | C34: =COUNTIFS(managers,B34,outcome,"W",'Regular Season Data'!$N:$N,"Y")&"-"&COUNTIFS(managers,B34,outcome,"L",'Regular Season Data'!$N:$N,"Y")&"-"&COUNTIFS(managers,B34,outcome,"T",'Regular Season Data'!$N:$N,"Y") -> 28-30-0 | D34: =COUNTIFS(managers,B34,outcome,"W",'Regular Season Data'!$N:$N,"N")&"-"&COUNTIFS(managers,B34,outcome,"L",'Regular Season Data'!$N:$N,"N")&"-"&COUNTIFS(managers,B34,outcome,"T",'Regular Season Data'!$N:$N,"N") -> 19-27-0 | F34: BR | G34: =COUNTIFS(managers,'SFFL Main Page'!F34,diff,">=50") -> 7 | H34: =COUNTIFS(managers,'SFFL Main Page'!F34,diff,"<=-50") -> 8 | I34: =G34-H34 -> -1 | N34: vs BR | O34: =COUNTIFS(managers,$N$33,opponent,S36,outcome,"W") -> 7 | P34: =COUNTIFS(managers,$N$33,opponent,S36,outcome,"L") -> 6 | Q34: =IFERROR((O34)/SUM(O34:P34),"") -> 0.53846154 | S34: Watty | X34: David | Y34: vs Brian | Z34: =COUNTIFS(managers,Y33,opponent,X35,outcome,"W") -> 6 | AA34: =COUNTIFS(managers,Y33,opponent,X35,outcome,"L") -> 18 | AB34: =COUNTIFS(managers,Y33,opponent,X35,outcome,"T") -> 0 | AC34: =IFERROR((Z34)/SUM(Z34:AB34),"") -> 0.25
B35: Arnold | C35: =COUNTIFS(managers,B35,outcome,"W",'Regular Season Data'!$N:$N,"Y")&"-"&COUNTIFS(managers,B35,outcome,"L",'Regular Season Data'!$N:$N,"Y")&"-"&COUNTIFS(managers,B35,outcome,"T",'Regular Season Data'!$N:$N,"Y") -> 18-17-0 | D35: =COUNTIFS(managers,B35,outcome,"W",'Regular Season Data'!$N:$N,"N")&"-"&COUNTIFS(managers,B35,outcome,"L",'Regular Season Data'!$N:$N,"N")&"-"&COUNTIFS(managers,B35,outcome,"T",'Regular Season Data'!$N:$N,"N") -> 11-24-0 | F35: Brent | G35: =COUNTIFS(managers,'SFFL Main Page'!F35,diff,">=50") -> 8 | H35: =COUNTIFS(managers,'SFFL Main Page'!F35,diff,"<=-50") -> 3 | I35: =G35-H35 -> 5 | N35: vs Russell | O35: =COUNTIFS(managers,$N$33,opponent,S37,outcome,"W") -> 7 | P35: =COUNTIFS(managers,$N$33,opponent,S37,outcome,"L") -> 12 | Q35: =IFERROR((O35)/SUM(O35:P35),"") -> 0.36842105 | S35: David | X35: Brian | Y35: Russell | Z35: {=SUM(COUNTIFS(managers,'SFFL Main Page'!Y35,opponent,{"Emily","Matt"},outcome,"W"))} -> 10 | AA35: {=SUM(COUNTIFS(managers,'SFFL Main Page'!Y35,opponent,{"Emily","Matt"},outcome,"L"))} -> 24 | AB35: {=SUM(COUNTIFS(managers,'SFFL Main Page'!Y35,opponent,{"Emily","Matt"},outcome,"T"))} -> 1 | AC35: =IFERROR((Z35)/SUM(Z35:AB35),"") -> 0.28571429 | AD35: BR
B36: BR | C36: =COUNTIFS(managers,B36,outcome,"W",'Regular Season Data'!$N:$N,"Y")&"-"&COUNTIFS(managers,B36,outcome,"L",'Regular Season Data'!$N:$N,"Y")&"-"&COUNTIFS(managers,B36,outcome,"T",'Regular Season Data'!$N:$N,"Y") -> 38-51-3 | D36: =COUNTIFS(managers,B36,outcome,"W",'Regular Season Data'!$N:$N,"N")&"-"&COUNTIFS(managers,B36,outcome,"L",'Regular Season Data'!$N:$N,"N")&"-"&COUNTIFS(managers,B36,outcome,"T",'Regular Season Data'!$N:$N,"N") -> 49-33-0 | F36: Brian | G36: =COUNTIFS(managers,'SFFL Main Page'!F36,diff,">=50") -> 12 | H36: =COUNTIFS(managers,'SFFL Main Page'!F36,diff,"<=-50") -> 11 | I36: =G36-H36 -> 1 | N36: vs Watty | O36: =COUNTIFS(managers,$N$33,opponent,S38,outcome,"W") -> 11 | P36: =COUNTIFS(managers,$N$33,opponent,S38,outcome,"L") -> 5 | Q36: =IFERROR((O36)/SUM(O36:P36),"") -> 0.6875 | S36: BR | X36: Russell | Y36: vs Emily | Z36: =COUNTIFS(managers,Y35,opponent,X37,outcome,"W") -> 7 | AA36: =COUNTIFS(managers,Y35,opponent,X37,outcome,"L") -> 14 | AB36: =COUNTIFS(managers,Y35,opponent,X37,outcome,"T") -> 0 | AC36: =IFERROR((Z36)/SUM(Z36:AB36),"") -> 0.33333333 | AD36: Russell
B37: Brent | C37: =COUNTIFS(managers,B37,outcome,"W",'Regular Season Data'!$N:$N,"Y")&"-"&COUNTIFS(managers,B37,outcome,"L",'Regular Season Data'!$N:$N,"Y")&"-"&COUNTIFS(managers,B37,outcome,"T",'Regular Season Data'!$N:$N,"Y") -> 54-25-1 | D37: =COUNTIFS(managers,B37,outcome,"W",'Regular Season Data'!$N:$N,"N")&"-"&COUNTIFS(managers,B37,outcome,"L",'Regular Season Data'!$N:$N,"N")&"-"&COUNTIFS(managers,B37,outcome,"T",'Regular Season Data'!$N:$N,"N") -> 41-27-0 | F37: Charles | G37: =COUNTIFS(managers,'SFFL Main Page'!F37,diff,">=50") -> 11 | H37: =COUNTIFS(managers,'SFFL Main Page'!F37,diff,"<=-50") -> 3 | I37: =G37-H37 -> 8 | N37: Russell | O37: {=SUM(COUNTIFS(managers,'SFFL Main Page'!N37,opponent,{"BR","David","Watty"},outcome,"W"))} -> 34 | P37: {=SUM(COUNTIFS(managers,'SFFL Main Page'!N37,opponent,{"BR","David","Watty"},outcome,"L"))} -> 17 | Q37: =IFERROR((O37)/SUM(O37:P37),"") -> 0.66666667 | S37: Russell | X37: Emily | Y37: vs Matt | Z37: =COUNTIFS(managers,Y35,opponent,X38,outcome,"W") -> 3 | AA37: =COUNTIFS(managers,Y35,opponent,X38,outcome,"L") -> 10 | AB37: =COUNTIFS(managers,Y35,opponent,X38,outcome,"T") -> 1 | AC37: =IFERROR((Z37)/SUM(Z37:AB37),"") -> 0.21428571 | AD37: Watty
B38: Brian | C38: =COUNTIFS(managers,B38,outcome,"W",'Regular Season Data'!$N:$N,"Y")&"-"&COUNTIFS(managers,B38,outcome,"L",'Regular Season Data'!$N:$N,"Y")&"-"&COUNTIFS(managers,B38,outcome,"T",'Regular Season Data'!$N:$N,"Y") -> 42-44-1 | D38: =COUNTIFS(managers,B38,outcome,"W",'Regular Season Data'!$N:$N,"N")&"-"&COUNTIFS(managers,B38,outcome,"L",'Regular Season Data'!$N:$N,"N")&"-"&COUNTIFS(managers,B38,outcome,"T",'Regular Season Data'!$N:$N,"N") -> 54-33-0 | F38: David | G38: =COUNTIFS(managers,'SFFL Main Page'!F38,diff,">=50") -> 7 | H38: =COUNTIFS(managers,'SFFL Main Page'!F38,diff,"<=-50") -> 9 | I38: =G38-H38 -> -2 | N38: vs BR | O38: =COUNTIFS(managers,$N$37,opponent,S40,outcome,"W") -> 11 | P38: =COUNTIFS(managers,$N$37,opponent,S40,outcome,"L") -> 4 | Q38: =IFERROR((O38)/SUM(O38:P38),"") -> 0.73333333 | S38: Watty | X38: Matt | Y38: Watty | Z38: {=SUM(COUNTIFS(managers,'SFFL Main Page'!Y38,opponent,{"David","Russell","BR"},outcome,"W"))} -> 20 | AA38: {=SUM(COUNTIFS(managers,'SFFL Main Page'!Y38,opponent,{"David","Russell","BR"},outcome,"L"))} -> 31 | AB38: {=SUM(COUNTIFS(managers,'SFFL Main Page'!Y38,opponent,{"David","Russell","Watty"},outcome,"T"))} -> 0 | AC38: =IFERROR((Z38)/SUM(Z38:AB38),"") -> 0.39215686
B39: Charles | C39: =COUNTIFS(managers,B39,outcome,"W",'Regular Season Data'!$N:$N,"Y")&"-"&COUNTIFS(managers,B39,outcome,"L",'Regular Season Data'!$N:$N,"Y")&"-"&COUNTIFS(managers,B39,outcome,"T",'Regular Season Data'!$N:$N,"Y") -> 38-40-0 | D39: =COUNTIFS(managers,B39,outcome,"W",'Regular Season Data'!$N:$N,"N")&"-"&COUNTIFS(managers,B39,outcome,"L",'Regular Season Data'!$N:$N,"N")&"-"&COUNTIFS(managers,B39,outcome,"T",'Regular Season Data'!$N:$N,"N") -> 44-26-0 | F39: Emily | G39: =COUNTIFS(managers,'SFFL Main Page'!F39,diff,">=50") -> 6 | H39: =COUNTIFS(managers,'SFFL Main Page'!F39,diff,"<=-50") -> 13 | I39: =G39-H39 -> -7 | N39: vs David | O39: =COUNTIFS(managers,$N$37,opponent,S41,outcome,"W") -> 12 | P39: =COUNTIFS(managers,$N$37,opponent,S41,outcome,"L") -> 7 | Q39: =IFERROR((O39)/SUM(O39:P39),"") -> 0.63157895 | S39: Russell | X39: Watty | Y39: vs Abby | Z39: =COUNTIFS(managers,Y38,opponent,X40,outcome,"W") -> 7 | AA39: =COUNTIFS(managers,Y38,opponent,X40,outcome,"L") -> 4 | AB39: =COUNTIFS(managers,Y38,opponent,X40,outcome,"T") -> 0 | AC39: =IFERROR((Z39)/SUM(Z39:AB39),"") -> 0.63636364 | AD39: BR
B40: David | C40: =COUNTIFS(managers,B40,outcome,"W",'Regular Season Data'!$N:$N,"Y")&"-"&COUNTIFS(managers,B40,outcome,"L",'Regular Season Data'!$N:$N,"Y")&"-"&COUNTIFS(managers,B40,outcome,"T",'Regular Season Data'!$N:$N,"Y") -> 44-41-1 | D40: =COUNTIFS(managers,B40,outcome,"W",'Regular Season Data'!$N:$N,"N")&"-"&COUNTIFS(managers,B40,outcome,"L",'Regular Season Data'!$N:$N,"N")&"-"&COUNTIFS(managers,B40,outcome,"T",'Regular Season Data'!$N:$N,"N") -> 41-47-0 | F40: Grayson | G40: =COUNTIFS(managers,'SFFL Main Page'!F40,diff,">=50") -> 3 | H40: =COUNTIFS(managers,'SFFL Main Page'!F40,diff,"<=-50") -> 2 | I40: =G40-H40 -> 1 | N40: vs Watty | O40: =COUNTIFS(managers,$N$37,opponent,S42,outcome,"W") -> 11 | P40: =COUNTIFS(managers,$N$37,opponent,S42,outcome,"L") -> 6 | Q40: =IFERROR((O40)/SUM(O40:P40),"") -> 0.64705882 | S40: BR | X40: Abby | Y40: vs Mark | Z40: =COUNTIFS(managers,Y38,opponent,X41,outcome,"W") -> 6 | AA40: =COUNTIFS(managers,Y38,opponent,X41,outcome,"L") -> 10 | AB40: =COUNTIFS(managers,Y38,opponent,X41,outcome,"T") -> 0 | AC40: =IFERROR((Z40)/SUM(Z40:AB40),"") -> 0.375 | AD40: David
...

Sheet Owner View
B2: Choose Owner | C2: Michael
C4: Regular Season | I4: Playoffs | M4: Overall
B5: Opponent | C5: Win | D5: Loss | E5: Tie | F5: Pct | G5: Pts Diff | H5: Pts For | I5: Win | J5: Loss | K5: Tie | L5: Pct | M5: Win | N5: Loss | O5: Tie | P5: Pct | S5: Matchup ID | T5: Owner | U5: Opponent | V5: Pts/ Wins | W5: W Margin | X5: Wins | Y5: Pts/ Loss | Z5: L Margin | AA5: Losses | AB5: Overall | AC5: Overall Margin | AD5: Pts/ Wins | AE5: W Margin | AF5: Wins | AG5: Pts/ Loss | AH5: L Margin | AI5: Losses | AJ5: Overall | AK5: Overall Margin | AL5: Total
A6: {=SUMPRODUCT((P6<=$P$6:$P$20)/COUNTIF($P$6:$P$20,$P$6:$P$20))} -> 5 | B6: Abby | C6: =COUNTIFS(managers,$C$2,opponent,B6,outcome,"W") -> 7 | D6: =COUNTIFS(managers,$C$2,opponent,B6,outcome,"L") -> 4 | E6: =COUNTIFS(managers,$C$2,opponent,B6,outcome,"T") -> 0 | F6: =IFERROR((C6+(0.5*E6))/SUM(C6:E6),"") -> 0.63636364 | G6: =SUMIFS(diff,managers,$C$2,opponent,B6) -> 48 | H6: =SUMIFS(points,managers,$C$2,opponent,B6) -> 988 | I6: =COUNTIFS('Playoff Data'!B:B,'Owner View'!$C$2,'Playoff Data'!C:C,'Owner View'!B6,'Playoff Data'!H:H,"W") -> 1 | J6: =COUNTIFS('Playoff Data'!B:B,'Owner View'!$C$2,'Playoff Data'!C:C,'Owner View'!B6,'Playoff Data'!H:H,"L") -> 1 | K6: =COUNTIFS('Playoff Data'!B:B,'Owner View'!$C$2,'Playoff Data'!C:C,'Owner View'!B6,'Playoff Data'!H:H,"T") -> 0 | L6: =IFERROR((I6+(0.5*K6))/SUM(I6:K6),"") -> 0.5 | M6: =C6+I6 -> 8 | N6: =D6+J6 -> 5 | O6: =E6+K6 -> 0 | P6: =IFERROR((M6+(0.5*O6))/SUM(M6:O6),"") -> 0.61538462 | S6: 1 | T6: Abby | U6: Arnold | V6: =IFERROR(AVERAGEIFS(points,managers,'Owner View'!T6,opponent,'Owner View'!U6,outcome,"W"),"") | W6: =IFERROR(V6-VLOOKUP(T6,'SFFL Main Page'!$B$4:$L$20,9,FALSE),"") | X6: =IFERROR(COUNTIFS(managers,'Owner View'!T6,opponent,'Owner View'!U6,outcome,"W"),"") -> 0 | Y6: =IFERROR(AVERAGEIFS(points,managers,'Owner View'!T6,opponent,'Owner View'!U6,outcome,"L"),"") | Z6: =IFERROR(Y6-VLOOKUP(T6,'SFFL Main Page'!$B$4:$L$20,10,FALSE),"") | AA6: =IFERROR(COUNTIFS(managers,'Owner View'!T6,opponent,'Owner View'!U6,outcome,"L"),"") -> 0 | AB6: =IFERROR(((V6*X6)+(Y6*AA6))/SUM(X6,AA6),"") | AC6: =IFERROR(AB6-VLOOKUP(T6,'SFFL Main Page'!$B$4:$L$20,8,FALSE),"") | AD6: =IFERROR(AVERAGEIFS(points,managers,'Owner View'!U6,opponent,'Owner View'!T6,outcome,"W"),"") | AE6: =IFERROR(AD6-VLOOKUP(U6,'SFFL Main Page'!$B$4:$L$20,9,FALSE),"") | AF6: =IFERROR(COUNTIFS(managers,'Owner View'!U6,opponent,'Owner View'!T6,outcome,"W"),"") -> 0 | AG6: =IFERROR(AVERAGEIFS(points,managers,'Owner View'!U6,opponent,'Owner View'!T6,outcome,"L"),"") | AH6: =IFERROR(AG6-VLOOKUP(U6,'SFFL Main Page'!$B$4:$L$20,10,FALSE),"") | AI6: =IFERROR(COUNTIFS(managers,'Owner View'!U6,opponent,'Owner View'!T6,outcome,"L"),"") -> 0 | AJ6: =IFERROR(((AD6*AF6)+(AG6*AI6))/SUM(AF6,AI6),"") | AK6: =IFERROR(AJ6-VLOOKUP(U6,'SFFL Main Page'!$B$4:$L$20,8,FALSE),"") | AL6: =IFERROR(AC6-AK6,"")
A7: {=SUMPRODUCT((P7<=$P$6:$P$20)/COUNTIF($P$6:$P$20,$P$6:$P$20))} -> 2 | B7: Arnold | C7: =COUNTIFS(managers,$C$2,opponent,B7,outcome,"W") -> 6 | D7: =COUNTIFS(managers,$C$2,opponent,B7,outcome,"L") -> 1 | E7: =COUNTIFS(managers,$C$2,opponent,B7,outcome,"T") -> 0 | F7: =IFERROR((C7+(0.5*E7))/SUM(C7:E7),"") -> 0.85714286 | G7: =SUMIFS(diff,managers,$C$2,opponent,B7) -> 149 | H7: =SUMIFS(points,managers,$C$2,opponent,B7) -> 824 | I7: =COUNTIFS('Playoff Data'!B:B,'Owner View'!$C$2,'Playoff Data'!C:C,'Owner View'!B7,'Playoff Data'!H:H,"W") -> 0 | J7: =COUNTIFS('Playoff Data'!B:B,'Owner View'!$C$2,'Playoff Data'!C:C,'Owner View'!B7,'Playoff Data'!H:H,"L") -> 0 | K7: =COUNTIFS('Playoff Data'!B:B,'Owner View'!$C$2,'Playoff Data'!C:C,'Owner View'!B7,'Playoff Data'!H:H,"T") -> 0 | L7: =IFERROR((I7+(0.5*K7))/SUM(I7:K7),"") | M7: =C7+I7 -> 6 | N7: =D7+J7 -> 1 | O7: =E7+K7 -> 0 | P7: =IFERROR((M7+(0.5*O7))/SUM(M7:O7),"") -> 0.85714286 | S7: 2 | T7: Abby | U7: BR | V7: =IFERROR(AVERAGEIFS(points,managers,'Owner View'!T7,opponent,'Owner View'!U7,outcome,"W"),"") -> 111 | W7: =IFERROR(V7-VLOOKUP(T7,'SFFL Main Page'!$B$4:$L$20,9,FALSE),"") -> 15.510638 | X7: =IFERROR(COUNTIFS(managers,'Owner View'!T7,opponent,'Owner View'!U7,outcome,"W"),"") -> 3 | Y7: =IFERROR(AVERAGEIFS(points,managers,'Owner View'!T7,opponent,'Owner View'!U7,outcome,"L"),"") -> 68.666667 | Z7: =IFERROR(Y7-VLOOKUP(T7,'SFFL Main Page'!$B$4:$L$20,10,FALSE),"") -> -1.2982456 | AA7: =IFERROR(COUNTIFS(managers,'Owner View'!T7,opponent,'Owner View'!U7,outcome,"L"),"") -> 6 | AB7: =IFERROR(((V7*X7)+(Y7*AA7))/SUM(X7,AA7),"") -> 82.777778 | AC7: =IFERROR(AB7-VLOOKUP(T7,'SFFL Main Page'!$B$4:$L$20,8,FALSE),"") -> 1.2777778 | AD7: =IFERROR(AVERAGEIFS(points,managers,'Owner View'!U7,opponent,'Owner View'!T7,outcome,"W"),"") -> 93.333333 | AE7: =IFERROR(AD7-VLOOKUP(U7,'SFFL Main Page'!$B$4:$L$20,9,FALSE),"") -> -8.4367816 | AF7: =IFERROR(COUNTIFS(managers,'Owner View'!U7,opponent,'Owner View'!T7,outcome,"W"),"") -> 6 | AG7: =IFERROR(AVERAGEIFS(points,managers,'Owner View'!U7,opponent,'Owner View'!T7,outcome,"L"),"") -> 68.333333 | AH7: =IFERROR(AG7-VLOOKUP(U7,'SFFL Main Page'!$B$4:$L$20,10,FALSE),"") -> -9.6071429 | AI7: =IFERROR(COUNTIFS(managers,'Owner View'!U7,opponent,'Owner View'!T7,outcome,"L"),"") -> 3 | AJ7: =IFERROR(((AD7*AF7)+(AG7*AI7))/SUM(AF7,AI7),"") -> 85 | AK7: =IFERROR(AJ7-VLOOKUP(U7,'SFFL Main Page'!$B$4:$L$20,8,FALSE),"") -> -4.9885057 | AL7: =IFERROR(AC7-AK7,"") -> 6.2662835
A8: {=SUMPRODUCT((P8<=$P$6:$P$20)/COUNTIF($P$6:$P$20,$P$6:$P$20))} -> 11 | B8: BR | C8: =COUNTIFS(managers,$C$2,opponent,B8,outcome,"W") -> 7 | D8: =COUNTIFS(managers,$C$2,opponent,B8,outcome,"L") -> 9 | E8: =COUNTIFS(managers,$C$2,opponent,B8,outcome,"T") -> 0 | F8: =IFERROR((C8+(0.5*E8))/SUM(C8:E8),"") -> 0.4375 | G8: =SUMIFS(diff,managers,$C$2,opponent,B8) -> -99 | H8: =SUMIFS(points,managers,$C$2,opponent,B8) -> 1461 | I8: =COUNTIFS('Playoff Data'!B:B,'Owner View'!$C$2,'Playoff Data'!C:C,'Owner View'!B8,'Playoff Data'!H:H,"W") -> 0 | J8: =COUNTIFS('Playoff Data'!B:B,'Owner View'!$C$2,'Playoff Data'!C:C,'Owner View'!B8,'Playoff Data'!H:H,"L") -> 0 | K8: =COUNTIFS('Playoff Data'!B:B,'Owner View'!$C$2,'Playoff Data'!C:C,'Owner View'!B8,'Playoff Data'!H:H,"T") -> 0 | L8: =IFERROR((I8+(0.5*K8))/SUM(I8:K8),"") | M8: =C8+I8 -> 7 | N8: =D8+J8 -> 9 | O8: =E8+K8 -> 0 | P8: =IFERROR((M8+(0.5*O8))/SUM(M8:O8),"") -> 0.4375 | S8: 3 | T8: Abby | U8: Brent | V8: =IFERROR(AVERAGEIFS(points,managers,'Owner View'!T8,opponent,'Owner View'!U8,outcome,"W"),"") -> 82 | W8: =IFERROR(V8-VLOOKUP(T8,'SFFL Main Page'!$B$4:$L$20,9,FALSE),"") -> -13.489362 | X8: =IFERROR(COUNTIFS(managers,'Owner View'!T8,opponent,'Owner View'!U8,outcome,"W"),"") -> 1 | Y8: =IFERROR(AVERAGEIFS(points,managers,'Owner View'!T8,opponent,'Owner View'!U8,outcome,"L"),"") -> 72.4 | Z8: =IFERROR(Y8-VLOOKUP(T8,'SFFL Main Page'!$B$4:$L$20,10,FALSE),"") -> 2.4350877 | AA8: =IFERROR(COUNTIFS(managers,'Owner View'!T8,opponent,'Owner View'!U8,outcome,"L"),"") -> 5 | AB8: =IFERROR(((V8*X8)+(Y8*AA8))/SUM(X8,AA8),"") -> 74 | AC8: =IFERROR(AB8-VLOOKUP(T8,'SFFL Main Page'!$B$4:$L$20,8,FALSE),"") -> -7.5 | AD8: =IFERROR(AVERAGEIFS(points,managers,'Owner View'!U8,opponent,'Owner View'!T8,outcome,"W"),"") -> 92 | AE8: =IFERROR(AD8-VLOOKUP(U8,'SFFL Main Page'!$B$4:$L$20,9,FALSE),"") -> -13.357895 | AF8: =IFERROR(COUNTIFS(managers,'Owner View'!U8,opponent,'Owner View'!T8,outcome,"W"),"") -> 5 | AG8: =IFERROR(AVERAGEIFS(points,managers,'Owner View'!U8,opponent,'Owner View'!T8,outcome,"L"),"") -> 79 | AH8: =IFERROR(AG8-VLOOKUP(U8,'SFFL Main Page'!$B$4:$L$20,10,FALSE),"") -> -4.5769231 | AI8: =IFERROR(COUNTIFS(managers,'Owner View'!U8,opponent,'Owner View'!T8,outcome,"L"),"") -> 1 | AJ8: =IFERROR(((AD8*AF8)+(AG8*AI8))/SUM(AF8,AI8),"") -> 89.833333 | AK8: =IFERROR(AJ8-VLOOKUP(U8,'SFFL Main Page'!$B$4:$L$20,8,FALSE),"") -> -7.7274775 | AL8: =IFERROR(AC8-AK8,"") -> 0.22747748
A9: {=SUMPRODUCT((P9<=$P$6:$P$20)/COUNTIF($P$6:$P$20,$P$6:$P$20))} -> 13 | B9: Brent | C9: =COUNTIFS(managers,$C$2,opponent,B9,outcome,"W") -> 4 | D9: =COUNTIFS(managers,$C$2,opponent,B9,outcome,"L") -> 7 | E9: =COUNTIFS(managers,$C$2,opponent,B9,outcome,"T") -> 0 | F9: =IFERROR((C9+(0.5*E9))/SUM(C9:E9),"") -> 0.36363636 | G9: =SUMIFS(diff,managers,$C$2,opponent,B9) -> -96 | H9: =SUMIFS(points,managers,$C$2,opponent,B9) -> 1004 | I9: =COUNTIFS('Playoff Data'!B:B,'Owner View'!$C$2,'Playoff Data'!C:C,'Owner View'!B9,'Playoff Data'!H:H,"W") -> 1 | J9: =COUNTIFS('Playoff Data'!B:B,'Owner View'!$C$2,'Playoff Data'!C:C,'Owner View'!B9,'Playoff Data'!H:H,"L") -> 1 | K9: =COUNTIFS('Playoff Data'!B:B,'Owner View'!$C$2,'Playoff Data'!C:C,'Owner View'!B9,'Playoff Data'!H:H,"T") -> 0 | L9: =IFERROR((I9+(0.5*K9))/SUM(I9:K9),"") -> 0.5 | M9: =C9+I9 -> 5 | N9: =D9+J9 -> 8 | O9: =E9+K9 -> 0 | P9: =IFERROR((M9+(0.5*O9))/SUM(M9:O9),"") -> 0.38461538 | S9: 4 | T9: Abby | U9: Brian | V9: =IFERROR(AVERAGEIFS(points,managers,'Owner View'!T9,opponent,'Owner View'!U9,outcome,"W"),"") -> 80.714286 | W9: =IFERROR(V9-VLOOKUP(T9,'SFFL Main Page'!$B$4:$L$20,9,FALSE),"") -> -14.775076 | X9: =IFERROR(COUNTIFS(managers,'Owner View'!T9,opponent,'Owner View'!U9,outcome,"W"),"") -> 7 | Y9: =IFERROR(AVERAGEIFS(points,managers,'Owner View'!T9,opponent,'Owner View'!U9,outcome,"L"),"") -> 69 | Z9: =IFERROR(Y9-VLOOKUP(T9,'SFFL Main Page'!$B$4:$L$20,10,FALSE),"") -> -0.96491228 | AA9: =IFERROR(COUNTIFS(managers,'Owner View'!T9,opponent,'Owner View'!U9,outcome,"L"),"") -> 2 | AB9: =IFERROR(((V9*X9)+(Y9*AA9))/SUM(X9,AA9),"") -> 78.111111 | AC9: =IFERROR(AB9-VLOOKUP(T9,'SFFL Main Page'!$B$4:$L$20,8,FALSE),"") -> -3.3888889 | AD9: =IFERROR(AVERAGEIFS(points,managers,'Owner View'!U9,opponent,'Owner View'!T9,outcome,"W"),"") -> 113 | AE9: =IFERROR(AD9-VLOOKUP(U9,'SFFL Main Page'!$B$4:$L$20,9,FALSE),"") -> 9.4479167 | AF9: =IFERROR(COUNTIFS(managers,'Owner View'!U9,opponent,'Owner View'!T9,outcome,"W"),"") -> 2 | AG9: =IFERROR(AVERAGEIFS(points,managers,'Owner View'!U9,opponent,'Owner View'!T9,outcome,"L"),"") -> 66 | AH9: =IFERROR(AG9-VLOOKUP(U9,'SFFL Main Page'!$B$4:$L$20,10,FALSE),"") -> -11.532468 | AI9: =IFERROR(COUNTIFS(managers,'Owner View'!U9,opponent,'Owner View'!T9,outcome,"L"),"") -> 7 | AJ9: =IFERROR(((AD9*AF9)+(AG9*AI9))/SUM(AF9,AI9),"") -> 76.444444 | AK9: =IFERROR(AJ9-VLOOKUP(U9,'SFFL Main Page'!$B$4:$L$20,8,FALSE),"") -> -15.538314 | AL9: =IFERROR(AC9-AK9,"") -> 12.149425
A10: {=SUMPRODUCT((P10<=$P$6:$P$20)/COUNTIF($P$6:$P$20,$P$6:$P$20))} -> 14 | B10: Brian | C10: =COUNTIFS(managers,$C$2,opponent,B10,outcome,"W") -> 6 | D10: =COUNTIFS(managers,$C$2,opponent,B10,outcome,"L") -> 9 | E10: =COUNTIFS(managers,$C$2,opponent,B10,outcome,"T") -> 0 | F10: =IFERROR((C10+(0.5*E10))/SUM(C10:E10),"") -> 0.4 | G10: =SUMIFS(diff,managers,$C$2,opponent,B10) -> 107 | H10: =SUMIFS(points,managers,$C$2,opponent,B10) -> 1395 | I10: =COUNTIFS('Playoff Data'!B:B,'Owner View'!$C$2,'Playoff Data'!C:C,'Owner View'!B10,'Playoff Data'!H:H,"W") -> 0 | J10: =COUNTIFS('Playoff Data'!B:B,'Owner View'!$C$2,'Playoff Data'!C:C,'Owner View'!B10,'Playoff Data'!H:H,"L") -> 1 | K10: =COUNTIFS('Playoff Data'!B:B,'Owner View'!$C$2,'Playoff Data'!C:C,'Owner View'!B10,'Playoff Data'!H:H,"T") -> 0 | L10: =IFERROR((I10+(0.5*K10))/SUM(I10:K10),"") -> 0 | M10: =C10+I10 -> 6 | N10: =D10+J10 -> 10 | O10: =E10+K10 -> 0 | P10: =IFERROR((M10+(0.5*O10))/SUM(M10:O10),"") -> 0.375 | S10: 5 | T10: Abby | U10: Charles | V10: =IFERROR(AVERAGEIFS(points,managers,'Owner View'!T10,opponent,'Owner View'!U10,outcome,"W"),"") -> 98.5 | W10: =IFERROR(V10-VLOOKUP(T10,'SFFL Main Page'!$B$4:$L$20,9,FALSE),"") -> 3.0106383 | X10: =IFERROR(COUNTIFS(managers,'Owner View'!T10,opponent,'Owner View'!U10,outcome,"W"),"") -> 2 | Y10: =IFERROR(AVERAGEIFS(points,managers,'Owner View'!T10,opponent,'Owner View'!U10,outcome,"L"),"") -> 69.5 | Z10: =IFERROR(Y10-VLOOKUP(T10,'SFFL Main Page'!$B$4:$L$20,10,FALSE),"") -> -0.46491228 | AA10: =IFERROR(COUNTIFS(managers,'Owner View'!T10,opponent,'Owner View'!U10,outcome,"L"),"") -> 4 | AB10: =IFERROR(((V10*X10)+(Y10*AA10))/SUM(X10,AA10),"") -> 79.166667 | AC10: =IFERROR(AB10-VLOOKUP(T10,'SFFL Main Page'!$B$4:$L$20,8,FALSE),"") -> -2.3333333 | AD10: =IFERROR(AVERAGEIFS(points,managers,'Owner View'!U10,opponent,'Owner View'!T10,outcome,"W"),"") -> 119 | AE10: =IFERROR(AD10-VLOOKUP(U10,'SFFL Main Page'!$B$4:$L$20,9,FALSE),"") -> 10.254878 | AF10: =IFERROR(COUNTIFS(managers,'Owner View'!U10,opponent,'Owner View'!T10,outcome,"W"),"") -> 4 | AG10: =IFERROR(AVERAGEIFS(points,managers,'Owner View'!U10,opponent,'Owner View'!T10,outcome,"L"),"") -> 75.5 | AH10: =IFERROR(AG10-VLOOKUP(U10,'SFFL Main Page'!$B$4:$L$20,10,FALSE),"") -> -9.2575758 | AI10: =IFERROR(COUNTIFS(managers,'Owner View'!U10,opponent,'Owner View'!T10,outcome,"L"),"") -> 2 | AJ10: =IFERROR(((AD10*AF10)+(AG10*AI10))/SUM(AF10,AI10),"") -> 104.5 | AK10: =IFERROR(AJ10-VLOOKUP(U10,'SFFL Main Page'!$B$4:$L$20,8,FALSE),"") -> 6.452027 | AL10: =IFERROR(AC10-AK10,"") -> -8.7853604
